<?xml version="1.0"?>
<robot name="food_del_robot"
  xmlns:xacro="http://www.ros.org/wiki/xacro">

  <xacro:arg name="use_sim" default="false"/>

  <!-- ============================================================
       Inertia macros
       ============================================================ -->

  <xacro:macro name="box_inertia" params="m l w h xyz rpy">
    <inertial>
      <origin xyz="${xyz}" rpy="${rpy}"/>
      <mass value="${m}"/>
      <inertia ixx="${(1/12.0) * m * (h*h + l*l)}" ixy="0" ixz="0"
               iyy="${(1/12.0) * m * (w*w + l*l)}" iyz="0"
               izz="${(1/12.0) * m * (w*w + h*h)}"/>
    </inertial>
  </xacro:macro>

  <xacro:macro name="cylinder_inertia" params="m r h xyz rpy">
    <inertial>
      <origin xyz="${xyz}" rpy="${rpy}"/>
      <mass value="${m}"/>
      <inertia ixx="${(1/12.0) * m * (3*r*r + h*h)}" ixy="0" ixz="0"
               iyy="${(1/12.0) * m * (3*r*r + h*h)}" iyz="0"
               izz="${0.5 * m * r*r}"/>
    </inertial>
  </xacro:macro>

  <xacro:macro name="sphere_inertia" params="m r xyz rpy">
    <inertial>
      <origin xyz="${xyz}" rpy="${rpy}"/>
      <mass value="${m}"/>
      <inertia ixx="${(2/5.0) * m * r*r}" ixy="0" ixz="0"
               iyy="${(2/5.0) * m * r*r}" iyz="0"
               izz="${(2/5.0) * m * r*r}"/>
    </inertial>
  </xacro:macro>

  <xacro:macro name="wheel_inertia" params="m r h xyz rpy">
    <inertial>
      <origin xyz="${xyz}" rpy="${rpy}"/>
      <mass value="${m}"/>
      <inertia ixx="${(1/12.0) * m * (3*r*r + h*h)}" ixy="0" ixz="0"
               iyy="${0.5 * m * r*r}"                 iyz="0"
               izz="${(1/12.0) * m * (3*r*r + h*h)}"/>
    </inertial>
  </xacro:macro>

  <!-- ============================================================
       Links
       ============================================================ -->

  <link name="base_footprint"/>

  <joint name="base_footprint_joint" type="fixed">
    <parent link="base_footprint"/>
    <child link="base_link"/>
    <origin xyz="0 0 0.01" rpy="0 0 0"/>
  </joint>

  <link name="base_link">
    <xacro:box_inertia m="10.0" l="0.42" w="0.2" h="0.2"
                       xyz="0 0 0.11" rpy="0 0 0"/>
    <visual>
      <origin xyz="0 0 0.213" rpy="0 0 0"/>
      <geometry>
        <mesh filename="package://food_del_robot_description/meshes/base_link.STL"/>
      </geometry>
      <material name="">
        <color rgba="1 1 1 1"/>
      </material>
    </visual>
    <collision>
      <origin xyz="0 0 0.11" rpy="0 0 0"/>
      <geometry>
        <box size="0.42 0.42 0.2"/>
      </geometry>
    </collision>
  </link>

  <link name="right_wheel_link">
    <xacro:wheel_inertia m="1.5" r="0.0655" h="0.045"
                         xyz="0 0 0" rpy="0 0 0"/>
    <visual>
      <origin xyz="0 0 0" rpy="0 0 0"/>
      <geometry>
        <mesh filename="package://food_del_robot_description/meshes/right_wheel_link.STL"/>
      </geometry>
      <material name="">
        <color rgba="0.3 0.3 0.3 1"/>
      </material>
    </visual>
    <collision>
      <origin xyz="0 0 0" rpy="1.5708 0 0"/>
      <geometry>
        <cylinder radius="0.0655" length="0.045"/>
      </geometry>
    </collision>
  </link>

  <joint name="right_wheel_base_joint" type="continuous">
    <origin xyz="0.0 -0.225 0.0555" rpy="0 0 0"/>
    <parent link="base_link"/>
    <child link="right_wheel_link"/>
    <axis xyz="0 1 0"/>
  </joint>

  <link name="left_wheel_link">
    <xacro:wheel_inertia m="1.5" r="0.0655" h="0.045"
                         xyz="0 0 0" rpy="0 0 0"/>
    <visual>
      <origin xyz="0 0 0" rpy="0 0 0"/>
      <geometry>
        <mesh filename="package://food_del_robot_description/meshes/left_wheel_link.STL"/>
      </geometry>
      <material name="">
        <color rgba="0.3 0.3 0.3 1"/>
      </material>
    </visual>
    <collision>
      <origin xyz="0 0 0" rpy="1.5708 0 0"/>
      <geometry>
        <cylinder radius="0.0655" length="0.045"/>
      </geometry>
    </collision>
  </link>

  <joint name="left_wheel_base_joint" type="continuous">
    <origin xyz="0 0.225 0.0555" rpy="0 0 0"/>
    <parent link="base_link"/>
    <child link="left_wheel_link"/>
    <axis xyz="0 1 0"/>
  </joint>

  <!-- ============================================================
       LiDAR — RPLidar A1
       ============================================================ -->
  <link name="lidar_link">
    <xacro:box_inertia m="0.01" l="0.1" w="0.1" h="0.02"
                       xyz="0 0 0" rpy="0 0 0"/>
    <visual>
      <origin xyz="0 0 0" rpy="0 0 0"/>
      <geometry>
        <mesh filename="package://food_del_robot_description/meshes/lidar_link.STL"/>
      </geometry>
      <material name="">
        <color rgba="0.79 0.82 0.93 1"/>
      </material>
    </visual>
    <collision>
      <origin xyz="0 0 0" rpy="0 0 0"/>
      <geometry>
        <box size="0.01 0.1 0.02"/>
      </geometry>
    </collision>
  </link>

  <joint name="lidar_base_link" type="fixed">
    <origin xyz="0.178 0 0.2436" rpy="0 0 0"/>
    <parent link="base_link"/>
    <child link="lidar_link"/>
    <axis xyz="0 0 0"/>
  </joint>

  <!-- ============================================================
       Camera — Intel RealSense D435
       ============================================================ -->
  <link name="camera_link">
    <xacro:box_inertia m="0.072" l="0.09" w="0.025" h="0.025"
                       xyz="0 0 0" rpy="0 0 0"/>
    <visual>
      <origin xyz="0 0 0" rpy="0 0 0"/>
      <geometry>
        <mesh filename="package://food_del_robot_description/meshes/camera_link.STL"/>
      </geometry>
      <material name="">
        <color rgba="0.79 0.82 0.93 1"/>
      </material>
    </visual>
    <collision>
      <origin xyz="0 0 0" rpy="0 0 0"/>
      <geometry>
        <box size="0.09 0.025 0.025"/>
      </geometry>
    </collision>
  </link>

  <joint name="camera_base_joint" type="fixed">
    <origin xyz="0.295 0.0185 0.195" rpy="0 -0.35 0"/>
    <parent link="base_link"/>
    <child link="camera_link"/>
    <axis xyz="0 0 0"/>
  </joint>

  <!-- ============================================================
       IMU
       ============================================================ -->
  <link name="imu_link">
    <xacro:box_inertia m="0.01" l="0.01" w="0.01" h="0.01"
                       xyz="0 0 0" rpy="0 0 0"/>
    <visual>
      <origin xyz="0 0 0" rpy="0 0 0"/>
      <geometry>
        <mesh filename="package://food_del_robot_description/meshes/imu_link.STL"/>
      </geometry>
      <material name="">
        <color rgba="0.3 0.3 0.3 1"/>
      </material>
    </visual>
    <collision>
      <origin xyz="0 0 0" rpy="0 0 0"/>
      <geometry>
        <box size="0.02 0.02 0.01"/>
      </geometry>
    </collision>
  </link>

  <joint name="imu_base_joint" type="fixed">
    <origin xyz="0 0 0.1106" rpy="0 0 0"/>
    <parent link="base_link"/>
    <child link="imu_link"/>
    <axis xyz="0 0 0"/>
  </joint>

  <!-- ============================================================
       Caster wheels
       ============================================================ -->
  <link name="caster1_link">
    <xacro:sphere_inertia m="0.108" r="0.0325" xyz="0 0 0" rpy="0 0 0"/>
    <visual><origin xyz="0 0 0" rpy="0 0 0"/>
      <geometry><mesh filename="package://food_del_robot_description/meshes/caster1_link.STL"/></geometry>
      <material name=""><color rgba="0.75 0.75 0.75 1"/></material>
    </visual>
    <collision><origin xyz="0 0 0" rpy="0 0 0"/>
      <geometry><sphere radius="0.0325"/></geometry>
    </collision>
  </link>
  <joint name="c1_b_joint" type="fixed">
    <origin xyz="-0.1845 -0.1559745 0.0225" rpy="0 0 0"/>
    <parent link="base_link"/><child link="caster1_link"/>
    <axis xyz="0 0 0"/>
  </joint>

  <link name="caster2_link">
    <xacro:sphere_inertia m="0.108" r="0.0325" xyz="0 0 0" rpy="0 0 0"/>
    <visual><origin xyz="0 0 0" rpy="0 0 0"/>
      <geometry><mesh filename="package://food_del_robot_description/meshes/caster2_link.STL"/></geometry>
      <material name=""><color rgba="0.75 0.75 0.75 1"/></material>
    </visual>
    <collision><origin xyz="0 0 0" rpy="0 0 0"/>
      <geometry><sphere radius="0.0325"/></geometry>
    </collision>
  </link>
  <joint name="c2_b_joint" type="fixed">
    <origin xyz="-0.1845 0.18303 0.0225" rpy="0 0 0"/>
    <parent link="base_link"/><child link="caster2_link"/>
    <axis xyz="0 0 0"/>
  </joint>

  <link name="caster3_link">
    <xacro:sphere_inertia m="0.108" r="0.0325" xyz="0 0 0" rpy="0 0 0"/>
    <visual><origin xyz="0 0 0" rpy="0 0 0"/>
      <geometry><mesh filename="package://food_del_robot_description/meshes/caster3_link.STL"/></geometry>
      <material name=""><color rgba="0.75 0.75 0.75 1"/></material>
    </visual>
    <collision><origin xyz="0 0 0" rpy="0 0 0"/>
      <geometry><sphere radius="0.0325"/></geometry>
    </collision>
  </link>
  <joint name="c3_b_joint" type="fixed">
    <origin xyz="0.1845 -0.15597 0.0225" rpy="0 0 0"/>
    <parent link="base_link"/><child link="caster3_link"/>
    <axis xyz="0 0 0"/>
  </joint>

  <link name="caster4_link">
    <xacro:sphere_inertia m="0.108" r="0.0325" xyz="0 0 0" rpy="0 0 0"/>
    <visual><origin xyz="0 0 0" rpy="0 0 0"/>
      <geometry><mesh filename="package://food_del_robot_description/meshes/caster4_link.STL"/></geometry>
      <material name=""><color rgba="0.75 0.75 0.75 1"/></material>
    </visual>
    <collision><origin xyz="0 0 0" rpy="0 0 0"/>
      <geometry><sphere radius="0.0325"/></geometry>
    </collision>
  </link>
  <joint name="c4_b_joint" type="fixed">
    <origin xyz="0.1845 0.18303 0.0225" rpy="0 0 0"/>
    <parent link="base_link"/><child link="caster4_link"/>
    <axis xyz="0 0 0"/>
  </joint>

</robot>