<?xml version="1.0" encoding="utf-8"?>
<!-- This URDF was automatically created by SolidWorks to URDF Exporter! Originally created by Stephen Brawner (brawner@gmail.com) 
     Commit Version: 1.6.0-4-g7f85cfe  Build Version: 1.6.7995.38578
     For more information, please see http://wiki.ros.org/sw_urdf_exporter -->
<robot
  name="Robot_Full_Design.SLDASM">
  <link
    name="base_link">
    <inertial>
      <origin
        xyz="0.0056707 0.0010627 0.32086"
        rpy="0 0 0" />
      <mass
        value="17.12" />
      <inertia
        ixx="0.30093"
        ixy="0.00060521"
        ixz="-3.1073E-05"
        iyy="0.32303"
        iyz="-3.7563E-08"
        izz="0.46879" />
    </inertial>
    <visual>
      <origin
        xyz="0 0 0"
        rpy="0 0 0" />
      <geometry>
        <mesh
          filename="package://Robot_Full_Design.SLDASM/meshes/base_link.STL" />
      </geometry>
      <material
        name="">
        <color
          rgba="0.29804 0.29804 0.29804 1" />
      </material>
    </visual>
    <collision>
      <origin
        xyz="0 0 0"
        rpy="0 0 0" />
      <geometry>
        <mesh
          filename="package://Robot_Full_Design.SLDASM/meshes/base_link.STL" />
      </geometry>
    </collision>
  </link>
  <link
    name="lidar_link">
    <inertial>
      <origin
        xyz="0.010632 -0.0016703 -0.018432"
        rpy="0 0 0" />
      <mass
        value="0.073085" />
      <inertia
        ixx="1.9581E-05"
        ixy="-1.0393E-07"
        ixz="-4.2839E-07"
        iyy="2.4125E-05"
        iyz="9.4269E-09"
        izz="4.1418E-05" />
    </inertial>
    <visual>
      <origin
        xyz="0 0 0"
        rpy="0 0 0" />
      <geometry>
        <mesh
          filename="package://Robot_Full_Design.SLDASM/meshes/lidar_link.STL" />
      </geometry>
      <material
        name="">
        <color
          rgba="0.79216 0.81961 0.93333 1" />
      </material>
    </visual>
    <collision>
      <origin
        xyz="0 0 0"
        rpy="0 0 0" />
      <geometry>
        <mesh
          filename="package://Robot_Full_Design.SLDASM/meshes/lidar_link.STL" />
      </geometry>
    </collision>
  </link>
  <joint
    name="base_lidar_joint"
    type="fixed">
    <origin
      xyz="0.17965 0.0011689 0.14817"
      rpy="0 0 0" />
    <parent
      link="base_link" />
    <child
      link="lidar_link" />
    <axis
      xyz="0 0 0" />
  </joint>
  <link
    name="imu_link">
    <inertial>
      <origin
        xyz="-1.2594E-05 -1.1909E-07 -0.0069553"
        rpy="0 0 0" />
      <mass
        value="0.013048" />
      <inertia
        ixx="2.9945E-06"
        ixy="4.6016E-12"
        ixz="2.1648E-08"
        iyy="1.9851E-06"
        iyz="2.4504E-14"
        izz="4.5735E-06" />
    </inertial>
    <visual>
      <origin
        xyz="0 0 0"
        rpy="0 0 0" />
      <geometry>
        <mesh
          filename="package://Robot_Full_Design.SLDASM/meshes/imu_link.STL" />
      </geometry>
      <material
        name="">
        <color
          rgba="0.79216 0.81961 0.93333 1" />
      </material>
    </visual>
    <collision>
      <origin
        xyz="0 0 0"
        rpy="0 0 0" />
      <geometry>
        <mesh
          filename="package://Robot_Full_Design.SLDASM/meshes/imu_link.STL" />
      </geometry>
    </collision>
  </link>
  <joint
    name="base_imu_joint"
    type="fixed">
    <origin
      xyz="4.5433E-05 3.0734E-05 0.011601"
      rpy="0 0 0" />
    <parent
      link="base_link" />
    <child
      link="imu_link" />
    <axis
      xyz="0 0 0" />
  </joint>
  <link
    name="camera_link">
    <inertial>
      <origin
        xyz="-0.016393 -0.014932 -1.9236E-05"
        rpy="0 0 0" />
      <mass
        value="0.084208" />
      <inertia
        ixx="4.7928E-05"
        ixy="-1.6932E-06"
        ixz="-2.8381E-08"
        iyy="1.5244E-05"
        iyz="2.4938E-09"
        izz="5.159E-05" />
    </inertial>
    <visual>
      <origin
        xyz="0 0 0"
        rpy="0 0 0" />
      <geometry>
        <mesh
          filename="package://Robot_Full_Design.SLDASM/meshes/camera_link.STL" />
      </geometry>
      <material
        name="">
        <color
          rgba="0.72941 0.35686 0.023529 1" />
      </material>
    </visual>
    <collision>
      <origin
        xyz="0 0 0"
        rpy="0 0 0" />
      <geometry>
        <mesh
          filename="package://Robot_Full_Design.SLDASM/meshes/camera_link.STL" />
      </geometry>
    </collision>
  </link>
  <joint
    name="base_camera_joint"
    type="fixed">
    <origin
      xyz="0.28915 0.017531 0.091186"
      rpy="0 -0.7854 0" />
    <parent
      link="base_link" />
    <child
      link="camera_link" />
    <axis
      xyz="0 0 0" />
  </joint>
  <link
    name="left_wheel_link">
    <inertial>
      <origin
        xyz="0.0071585 -0.22416 0.29824"
        rpy="0 0 0" />
      <mass
        value="21.772" />
      <inertia
        ixx="2.6849"
        ixy="-0.0030784"
        ixz="0.010532"
        iyy="2.6619"
        iyz="0.0037934"
        izz="0.8177" />
    </inertial>
    <visual>
      <origin
        xyz="0 0 0"
        rpy="0 0 0" />
      <geometry>
        <mesh
          filename="package://Robot_Full_Design.SLDASM/meshes/left_wheel_link.STL" />
      </geometry>
      <material
        name="">
        <color
          rgba="1 1 1 1" />
      </material>
    </visual>
    <collision>
      <origin
        xyz="0 0 0"
        rpy="0 0 0" />
      <geometry>
        <mesh
          filename="package://Robot_Full_Design.SLDASM/meshes/left_wheel_link.STL" />
      </geometry>
    </collision>
  </link>
  <joint
    name="base_left_wheel_joint"
    type="continuous">
    <origin
      xyz="0.00021891 0.22503 -0.04"
      rpy="0 0 0" />
    <parent
      link="base_link" />
    <child
      link="left_wheel_link" />
    <axis
      xyz="0 1 0" />
  </joint>
  <link
    name="right_wheel_link">
    <inertial>
      <origin
        xyz="0.0071585 0.22584 0.29824"
        rpy="0 0 0" />
      <mass
        value="21.772" />
      <inertia
        ixx="2.6849"
        ixy="-0.0030784"
        ixz="0.010532"
        iyy="2.6619"
        iyz="0.0037934"
        izz="0.8177" />
    </inertial>
    <visual>
      <origin
        xyz="0 0 0"
        rpy="0 0 0" />
      <geometry>
        <mesh
          filename="package://Robot_Full_Design.SLDASM/meshes/right_wheel_link.STL" />
      </geometry>
      <material
        name="">
        <color
          rgba="1 1 1 1" />
      </material>
    </visual>
    <collision>
      <origin
        xyz="0 0 0"
        rpy="0 0 0" />
      <geometry>
        <mesh
          filename="package://Robot_Full_Design.SLDASM/meshes/right_wheel_link.STL" />
      </geometry>
    </collision>
  </link>
  <joint
    name="base_right_wheel_joint"
    type="continuous">
    <origin
      xyz="0.00021891 -0.22497 -0.04"
      rpy="0 0 0" />
    <parent
      link="base_link" />
    <child
      link="right_wheel_link" />
    <axis
      xyz="0 1 0" />
  </joint>
</robot>